<sdf version="1.8">
  <model name="MR-Buggy3">
    <pose>0 0 .04 0 0 0</pose>
    <self_collide>false</self_collide>
    <static>false</static>
    <link name="MR-Buggy3/Base">
      <inertial>
        <pose>0 0 0 0 0 0</pose>
        <mass>3.0</mass>
        <inertia>
          <ixx>0.0054</ixx>
          <ixy>0</ixy>
          <ixz>0</ixz>
          <iyy>0.0252</iyy>
          <iyz>0</iyz>
          <izz>0.0252</izz>
        </inertia>
      </inertial>
      <visual name="MR-Buggy3/BaseVisual">
        <pose>.1371 0 -.0115 -0.018 0 1.5707</pose>
        <geometry>
          <mesh>
            <uri>/home/ingejohan/Workspaces/ros2_cpp_ws/src/udemy_ros2_pkg/models/RC/BaseReduced.dae</uri>
          </mesh>
        </geometry>
      </visual>
      <visual name="MR-Buggy3/TopVisual">
        <pose>.1371 0 -.0115 -0.018 0 1.5707</pose>
        <geometry>
          <mesh>
            <uri>/home/ingejohan/Workspaces/ros2_cpp_ws/src/udemy_ros2_pkg/models/RC/TopReduced.dae</uri>
          </mesh>
        </geometry>
      </visual>
      <collision name="MR-Buggy3/BaseCollision">
        <pose>0 0 .06 0 0 0</pose>
        <geometry>
          <box>
            <size>.3 .09 .12</size>
          </box>
        </geometry>
      </collision>
      <sensor name="NPUSim/Camera" type="camera">
        <pose>.16 0 .3 0 0.5 0</pose>
        <always_on>1</always_on>
        <update_rate>10</update_rate>
        <camera>
          <horizontal_fov>1.5</horizontal_fov>
          <image>
            <width>300</width>
            <height>300</height>
            <format>R8G8B8</format>
          </image>
          <clip>
            <near>0.1</near>
            <far>1000</far>
          </clip>
        </camera>
        <topic>NPU/image_sim</topic>
        <enable_metrics>true</enable_metrics>
      </sensor>
    </link>
    <link name="MR-Buggy3/FrontRightWheel">
      <pose relative_to="MR-Buggy3/FrontRightWheelJoint">0 0 0 0 0 0</pose>
      <inertial>
        <mass>.05</mass>
        <inertia>
          <ixx>0.00003331</ixx>
          <ixy>0</ixy>
          <ixz>0</ixz>
          <iyy>0.0000204</iyy>
          <iyz>0</iyz>
          <izz>0.0000204</izz>
        </inertia>
      </inertial>
      <gravity>true</gravity>
      <velocity_decay/>
      <visual name="MR-Buggy3/FrontRightWheelVisual">
        <pose>0 0 0 0 0 0</pose>
        <geometry>
          <mesh>
            <uri>/home/ingejohan/Workspaces/ros2_cpp_ws/src/udemy_ros2_pkg/models/RC/Wheel.dae</uri>
          </mesh>
        </geometry>
      </visual>
      <collision name="MR-Buggy3/FrontRightWheelCollision">
        <pose>0 .015 0 -1.5707 0 0</pose>
        <geometry>
          <cylinder>
            <length>0.03</length>
            <radius>0.0365</radius>
          </cylinder>
        </geometry>
        <surface>
          <friction>
            <ode>
              <mu>0.5</mu>
              <mu2>1.0</mu2>
              <fdir1>0 0 1</fdir1>
            </ode>
          </friction>
        </surface>
      </collision>
    </link>
    <link name="MR-Buggy3/FrontRightWheelSteering">
      <pose relative_to="MR-Buggy3/FrontRightWheelSteeringJoint">0 0 0 0 0 0</pose>
      <inertial>
        <mass>0.005</mass>
        <inertia>
          <ixx>0.0000018</ixx>
          <iyy>0.0000018</iyy>
          <izz>0.0000018</izz>
        </inertia>
      </inertial>
    </link>
    <link name="MR-Buggy3/FrontLeftWheel">
      <pose relative_to="MR-Buggy3/FrontLeftWheelJoint">0 0 0 0 0 0</pose>
      <inertial>
        <mass>.05</mass>
        <inertia>
          <ixx>0.00003331</ixx>
          <ixy>0</ixy>
          <ixz>0</ixz>
          <iyy>0.0000204</iyy>
          <iyz>0</iyz>
          <izz>0.0000204</izz>
        </inertia>
      </inertial>
      <gravity>true</gravity>
      <velocity_decay/>
      <visual name="MR-Buggy3/FrontLeftWheelVisual">
        <pose>0 0 0 0 0 3.14159</pose>
        <geometry>
          <mesh>
            <uri>/home/ingejohan/Workspaces/ros2_cpp_ws/src/udemy_ros2_pkg/models/RC/Wheel.dae</uri>
          </mesh>
        </geometry>
      </visual>
      <collision name="MR-Buggy3/FrontLeftWheelCollision">
        <pose>0 -.015 0 -1.5707 0 0</pose>
        <geometry>
          <cylinder>
            <length>0.03</length>
            <radius>0.0365</radius>
          </cylinder>
        </geometry>
        <surface>
          <friction>
            <ode>
              <mu>0.5</mu>
              <mu2>1.0</mu2>
              <fdir1>0 0 1</fdir1>
            </ode>
          </friction>
        </surface>
      </collision>
    </link>
    <link name="MR-Buggy3/FrontLeftWheelSteering">
      <pose relative_to="MR-Buggy3/FrontLeftWheelSteeringJoint">0 0 0 0 0 0</pose>
      <inertial>
        <mass>0.005</mass>
        <inertia>
          <ixx>0.0000018</ixx>
          <iyy>0.0000018</iyy>
          <izz>0.0000018</izz>
        </inertia>
      </inertial>
    </link>
    <link name="MR-Buggy3/RearRightWheel">
      <pose relative_to="MR-Buggy3/RearRightWheelJoint">0 0 0 0 0 0</pose>
      <inertial>
        <mass>.05</mass>
        <inertia>
          <ixx>0.00003331</ixx>
          <ixy>0</ixy>
          <ixz>0</ixz>
          <iyy>0.0000204</iyy>
          <iyz>0</iyz>
          <izz>0.0000204</izz>
        </inertia>
      </inertial>
      <gravity>true</gravity>
      <velocity_decay/>
      <visual name="MR-Buggy3/RearRightWheelVisual">
        <pose>0 0 0 0 0 0</pose>
        <geometry>
          <mesh>
            <uri>/home/ingejohan/Workspaces/ros2_cpp_ws/src/udemy_ros2_pkg/models/RC/Wheel.dae</uri>
          </mesh>
        </geometry>
      </visual>
      <collision name="MR-Buggy3/RearRightWheelCollision">
        <pose>0 .015 0 -1.5707 0 0</pose>
        <geometry>
          <cylinder>
            <length>0.03</length>
            <radius>0.0365</radius>
          </cylinder>
        </geometry>
        <surface>
          <friction>
            <ode>
              <mu>0.5</mu>
              <mu2>1.0</mu2>
              <fdir1>0 0 1</fdir1>
            </ode>
          </friction>
        </surface>
      </collision>
    </link>
    <link name="MR-Buggy3/RearLeftWheel">
      <pose relative_to="MR-Buggy3/RearLeftWheelJoint">0 0 0 0 0 0</pose>
      <inertial>
        <mass>.05</mass>
        <inertia>
          <ixx>0.00003331</ixx>
          <ixy>0</ixy>
          <ixz>0</ixz>
          <iyy>0.0000204</iyy>
          <iyz>0</iyz>
          <izz>0.0000204</izz>
        </inertia>
      </inertial>
      <gravity>true</gravity>
      <velocity_decay/>
      <visual name="MR-Buggy3/RearLeftWheelVisual">
        <pose>0 0 0 0 0 3.14159</pose>
        <geometry>
          <mesh>
            <uri>/home/ingejohan/Workspaces/ros2_cpp_ws/src/udemy_ros2_pkg/models/RC/Wheel.dae</uri>
          </mesh>
        </geometry>
      </visual>
      <collision name="MR-Buggy3/RearLeftWheelCollision">
        <pose>0 -.015 0 -1.5707 0 0</pose>
        <geometry>
          <cylinder>
            <length>0.03</length>
            <radius>0.0365</radius>
          </cylinder>
        </geometry>
        <surface>
          <friction>
            <ode>
              <mu>0.5</mu>
              <mu2>1.0</mu2>
              <fdir1>0 0 1</fdir1>
            </ode>
          </friction>
        </surface>
      </collision>
    </link>

<!-- Lidar -->
  <!-- <model name="model_with_lidar"> -->
    <link name="lidar_link">
      <pose>0.08 0 0.065 0 0 0</pose>
      <inertial>
        <mass>0.0001</mass>
        <inertia>
          <ixx>0.000166667</ixx>
          <iyy>0.000166667</iyy>
          <izz>0.000166667</izz>
        </inertia>
      </inertial>
      <collision name="collision">
        <geometry>
          <box>
            <size>0.1 0.1 0.1</size>
          </box>
        </geometry>
      </collision>
      <visual name="visual">
        <geometry>
          <box>
            <size>0.1 0.1 0.1</size>
          </box>
        </geometry>
      </visual>

      <sensor name='gpu_lidar' type='gpu_lidar'>
        <!-- <pose relative_to="lidar_link">0 0 0 0 0 0</pose> -->
        <topic>lidar</topic>
        <update_rate>10</update_rate>
        <ray>
          <scan>
            <horizontal>
              <samples>8</samples>
              <resolution>1</resolution>
              <min_angle>-1.396263</min_angle>
              <max_angle>1.396263</max_angle>
            </horizontal>
            <vertical>
              <samples>1</samples>
              <resolution>0.01</resolution>
              <min_angle>0</min_angle>
              <max_angle>0</max_angle>
            </vertical>
          </scan>
          <range>
            <min>0.08</min>
            <max>10.0</max>
            <resolution>0.01</resolution>
          </range>
        </ray>
        <alwaysOn>1</alwaysOn>
        <visualize>true</visualize>
      </sensor>
    </link>
    <static>true</static>
  <!-- </model> -->

  

    <joint name='lidar_sensor_joint' type='fixed'>
      <parent>MR-Buggy3/Base</parent>
      <child>lidar_link</child>
    </joint>

<!-- Lidar end -->

    
    <joint name="MR-Buggy3/FrontRightWheelSteeringJoint" type="revolute">
      <parent>MR-Buggy3/Base</parent>
      <child>MR-Buggy3/FrontRightWheelSteering</child>
      <pose relative_to="MR-Buggy3/Base">.112 -.10 0 0 0 0</pose>
      <axis>
        <xyz>0 0 1</xyz>
        <limit>
          <lower>-0.6</lower>
          <upper>0.6</upper>
          <velocity>1.0</velocity>
          <effort>25</effort>
        </limit>
        <use_parent_model_frame>1</use_parent_model_frame>
      </axis>
    </joint>
    <joint name="MR-Buggy3/FrontRightWheelJoint" type="revolute">
      <parent>MR-Buggy3/FrontRightWheelSteering</parent>
      <child>MR-Buggy3/FrontRightWheel</child>
      <pose relative_to="MR-Buggy3/FrontRightWheelSteeringJoint">0 0 0 0 0 0</pose>
      <axis>
        <xyz>0 1 0</xyz>
        <limit>
          <lower>-1.79769e+308</lower>
          <upper>1.79769e+308</upper>
        </limit>
        <dynamics>
          <spring_reference>0</spring_reference>
          <spring_stiffness>0</spring_stiffness>
        </dynamics>
        <use_parent_model_frame>1</use_parent_model_frame>
      </axis>
    </joint>
    <joint name="MR-Buggy3/FrontLeftWheelSteeringJoint" type="revolute">
      <parent>MR-Buggy3/Base</parent>
      <child>MR-Buggy3/FrontLeftWheelSteering</child>
      <pose relative_to="MR-Buggy3/Base">.112 .10 0 0 0 0</pose>
      <axis>
        <xyz>0 0 1</xyz>
        <limit>
          <lower>-0.6</lower>
          <upper>0.6</upper>
          <velocity>1.0</velocity>
          <effort>25</effort>
        </limit>
        <use_parent_model_frame>1</use_parent_model_frame>
      </axis>
    </joint>
    <joint name="MR-Buggy3/FrontLeftWheelJoint" type="revolute">
      <parent>MR-Buggy3/FrontLeftWheelSteering</parent>
      <child>MR-Buggy3/FrontLeftWheel</child>
      <pose relative_to="MR-Buggy3/FrontLeftWheelSteeringJoint">0 0 0 0 0 0</pose>
      <axis>
        <xyz>0 1 0</xyz>
        <limit>
          <lower>-1.79769e+308</lower>
          <upper>1.79769e+308</upper>
        </limit>
        <dynamics>
          <spring_reference>0</spring_reference>
          <spring_stiffness>0</spring_stiffness>
        </dynamics>
        <use_parent_model_frame>1</use_parent_model_frame>
      </axis>
    </joint>
    <joint name="MR-Buggy3/RearRightWheelJoint" type="revolute">
      <parent>MR-Buggy3/Base</parent>
      <child>MR-Buggy3/RearRightWheel</child>
      <pose relative_to="MR-Buggy3/Base">-.1135 -.10 0 0 0 0</pose>
      <axis>
        <xyz>0 1 0</xyz>
        <limit>
          <lower>-1.79769e+308</lower>
          <upper>1.79769e+308</upper>
        </limit>
        <dynamics>
          <spring_reference>0</spring_reference>
          <spring_stiffness>0</spring_stiffness>
        </dynamics>
        <use_parent_model_frame>1</use_parent_model_frame>
      </axis>
    </joint>
    <joint name="MR-Buggy3/RearLeftWheelJoint" type="revolute">
      <parent>MR-Buggy3/Base</parent>
      <child>MR-Buggy3/RearLeftWheel</child>
      <pose relative_to="MR-Buggy3/Base">-.1135 .10 0 0 0 0</pose>
      <axis>
        <xyz>0 1 0</xyz>
        <limit>
          <lower>-1.79769e+308</lower>
          <upper>1.79769e+308</upper>
        </limit>
        <dynamics>
          <spring_reference>0</spring_reference>
          <spring_stiffness>0</spring_stiffness>
        </dynamics>
        <use_parent_model_frame>1</use_parent_model_frame>
      </axis>
    </joint>
    <plugin
      filename="ignition-gazebo-ackermann-steering-system"
      name="ignition::gazebo::systems::AckermannSteering">
      <left_joint>MR-Buggy3/FrontLeftWheelJoint</left_joint>
      <left_joint>MR-Buggy3/RearLeftWheelJoint</left_joint>
      <right_joint>MR-Buggy3/FrontRightWheelJoint</right_joint>
      <right_joint>MR-Buggy3/FrontRightWheelJoint</right_joint>
      <left_steering_joint>MR-Buggy3/FrontLeftWheelSteeringJoint</left_steering_joint>
      <right_steering_joint>MR-Buggy3/FrontRightWheelSteeringJoint</right_steering_joint>
      <kingpin_width>.18</kingpin_width>
      <steering_limit>0.5</steering_limit>
      <wheel_base>.2255</wheel_base>
      <wheel_separation>.2</wheel_separation>
      <wheel_radius>0.0365</wheel_radius>
      <min_velocity>-100</min_velocity>
      <max_velocity>100</max_velocity>
      <min_acceleration>-5</min_acceleration>
      <max_acceleration>5</max_acceleration>
      <topic>/cmd_vel</topic>
    </plugin>
  </model>
</sdf>
